<?xml version="1.0"?>
<robot xmlns:xacro="http://www.ros.org/wiki/xacro" name="diff_bot">

    <!--................................ INERTIA MATRICES .............................. -->

    <xacro:macro name="cylinder_inertia" params="m r h">
        <inertia ixx="${m * (3 * r * r + h * h) / 12}" ixy="0" ixz="0" iyy="${m * (3 * r * r + h * h) / 12}" iyz="0" izz="${m * r * r / 2}" />
    </xacro:macro>

    <xacro:macro name="box_inertia" params="m x y z">
        <inertia ixx="${m * (y * y + z * z) / 12}" ixy="0" ixz="0" iyy="${m * (x * x + z * z) / 12}" iyz="0" izz="${m * (y * y + x * x) / 12}" />
    </xacro:macro>

    <xacro:macro name="sphere_inertia" params="m r">
        <inertia ixx="${2 * m * r * r / 5}" ixy="0" ixz="0" iyy="${2 * m * r * r / 5}" iyz="0" izz="${2 * m * r * r / 5}" />
    </xacro:macro>

    
    <!-- ............................... MAIN WHEEL DEFINITION .............................. -->

    <xacro:macro name="main_wheel" params="dexterity origin_x origin_y origin_z">
        <link name="${dexterity}_wheel">
            <collision>
                <origin xyz="0 0 0" rpy="0 ${pi/2} ${pi/2}" />
                <geometry>
                    <cylinder length="${main_wheel_width}" radius="${main_wheel_radius}"/>
                </geometry>
                <self_collide>false</self_collide>
            </collision>

            <inertial>
                <origin xyz="0 0 0" rpy="0 ${pi/2} ${pi/2}" />
                <mass value="${main_wheel_mass}"/>
                <xacro:cylinder_inertia m="${main_wheel_mass}" r="${main_wheel_radius}" h="${main_wheel_width}"/>
            </inertial>

            <visual>
                <origin xyz="0 0 0" rpy="0 ${pi/2} ${pi/2}" />
                <geometry>
                    <cylinder length="${main_wheel_width}" radius="${main_wheel_radius}"/>
                </geometry>
            </visual>

            <mu>5.0</mu>
        </link>

        <joint name="${dexterity}_wheel_joint" type="continuous">
            <parent link="base_link"/>
            <child link="${dexterity}_wheel"/>
            <origin xyz="${origin_x} ${origin_y} ${origin_z}" rpy="0 0 0" />
            <axis xyz="0 1 0" rpy="0 0 0" />
        </joint>

        <gazebo reference="${dexterity}_wheel">
            <material>Gazebo/Red</material>
        </gazebo>
    </xacro:macro>
    
    
    
    <!-- ............................... CASTOR WHEEL DEFINITION .............................. -->

    <xacro:macro name="castor_wheel" params="cardinality dexterity origin_x origin_y origin_z">
        <link name="${cardinality}_${dexterity}_castor_wheel">
            <collision>
                <origin xyz="0 0 0" rpy="0 ${pi/2} ${pi/2}" />
                <geometry>
                    <sphere radius="${castor_wheel_radius}"/>
                </geometry>
            </collision>

            <inertial>
                <origin xyz="0 0 0" rpy="0 0 0" />
                <mass value="${castor_wheel_mass}"/>
                <xacro:sphere_inertia m="${castor_wheel_mass}" r="${castor_wheel_radius}"/>
            </inertial>

            <visual>
                <origin xyz="0 0 0" rpy="0 ${pi/2} ${pi/2}" />
                <geometry>
                    <sphere radius="${castor_wheel_radius}"/>
                </geometry>
            </visual>

            <mu>0.0</mu>
        </link>

        <joint name="${cardinality}_${dexterity}_castor_wheel_joint" type="fixed">
            <parent link="base_link"/>
            <child link="${cardinality}_${dexterity}_castor_wheel"/>
            <origin xyz="${origin_x} ${origin_y} ${origin_z}" rpy="0 0 0" />
            <axis xyz="0 1 0" rpy="0 0 0" />
        </joint>

        <gazebo reference="${cardinality}_${dexterity}_castor_wheel">
            <material>Gazebo/Red</material>
        </gazebo>
    </xacro:macro>


    

</robot>